[36m[2025-04-25 01:35:00 DEBUG] [__init__:101][39m ###############################################################################
[36m[2025-04-25 01:35:00 DEBUG] [__init__:102][39m Running command 'run'
[36m[2025-04-25 01:35:00 DEBUG] [__init__:106][39m Using settings file '/root/.chaostoolkit/settings.yaml'
[36m[2025-04-25 01:35:01 DEBUG] [settings:31][39m The Chaos Toolkit settings file could not be found at '/root/.chaostoolkit/settings.yaml'.
[36m[2025-04-25 01:35:01 DEBUG] [__init__:472][39m No controls to apply on 'loader'
[36m[2025-04-25 01:35:01 DEBUG] [__init__:472][39m No controls to apply on 'loader'
[36m[2025-04-25 01:35:01 DEBUG] [caching:24][39m Building activity cache...
[36m[2025-04-25 01:35:01 DEBUG] [caching:35][39m Cached 4 activities
[32m[2025-04-25 01:35:01 INFO] [experiment:59][39m Validating the experiment's syntax
[36m[2025-04-25 01:35:01 DEBUG] [configuration:64][39m Loading configuration...
[36m[2025-04-25 01:35:01 DEBUG] [secret:79][39m Loading secrets...
[36m[2025-04-25 01:35:01 DEBUG] [secret:104][39m Done loading secrets
[36m[2025-04-25 01:35:01 DEBUG] [caching:42][39m Clearing activities cache
[31m[2025-04-25 01:35:01 ERROR] [run:188][39m path 'docker' cannot be found, in activity 'parar_container_redis'
[36m[2025-04-25 01:35:01 DEBUG] [run:189][39m path 'docker' cannot be found, in activity 'parar_container_redis'
[36m[2025-04-25 01:38:50 DEBUG] [__init__:101] ###############################################################################
[36m[2025-04-25 01:38:50 DEBUG] [__init__:102] Running command 'run'
[36m[2025-04-25 01:38:50 DEBUG] [__init__:106] Using settings file '/root/.chaostoolkit/settings.yaml'
[36m[2025-04-25 01:38:50 DEBUG] [settings:31] The Chaos Toolkit settings file could not be found at '/root/.chaostoolkit/settings.yaml'.
[36m[2025-04-25 01:38:50 DEBUG] [__init__:472] No controls to apply on 'loader'
[36m[2025-04-25 01:38:50 DEBUG] [__init__:472] No controls to apply on 'loader'
[36m[2025-04-25 01:38:50 DEBUG] [caching:24] Building activity cache...
[36m[2025-04-25 01:38:50 DEBUG] [caching:35] Cached 4 activities
[32m[2025-04-25 01:38:50 INFO] [experiment:59] Validating the experiment's syntax
[36m[2025-04-25 01:38:50 DEBUG] [configuration:64] Loading configuration...
[36m[2025-04-25 01:38:50 DEBUG] [secret:79] Loading secrets...
[36m[2025-04-25 01:38:50 DEBUG] [secret:104] Done loading secrets
[32m[2025-04-25 01:38:50 INFO] [experiment:112] Experiment looks valid
[36m[2025-04-25 01:38:50 DEBUG] [caching:42] Clearing activities cache
[36m[2025-04-25 01:38:50 DEBUG] [run:224] Runtime strategies: hypothesis - default / rollbacks - default
[36m[2025-04-25 01:38:50 DEBUG] [caching:24] Building activity cache...
[36m[2025-04-25 01:38:50 DEBUG] [caching:35] Cached 4 activities
[36m[2025-04-25 01:38:50 DEBUG] [configuration:64] Loading configuration...
[36m[2025-04-25 01:38:50 DEBUG] [secret:79] Loading secrets...
[36m[2025-04-25 01:38:50 DEBUG] [secret:104] Done loading secrets
[36m[2025-04-25 01:38:50 DEBUG] [configuration:161] Loading dynamic configuration...
[32m[2025-04-25 01:38:50 INFO] [run:440] Running experiment: Teste simples de falha no Redis
[36m[2025-04-25 01:38:50 DEBUG] [__init__:67] Initializing controls
[32m[2025-04-25 01:38:50 INFO] [run:471] Steady-state strategy: default
[32m[2025-04-25 01:38:50 INFO] [run:477] Rollbacks strategy: default
[36m[2025-04-25 01:38:50 DEBUG] [__init__:472] No controls to apply on 'experiment'
[36m[2025-04-25 01:38:50 DEBUG] [run:654] Running steady-state hypothesis before the method
[32m[2025-04-25 01:38:50 INFO] [hypothesis:205] Steady state hypothesis: AplicaÃ§Ã£o estÃ¡ saudÃ¡vel
[36m[2025-04-25 01:38:50 DEBUG] [__init__:472] No controls to apply on 'hypothesis'
[36m[2025-04-25 01:38:50 DEBUG] [__init__:472] No controls to apply on 'activity'
[32m[2025-04-25 01:38:50 INFO] [activity:232] Probe: verifica_servico_aplicacao
[36m[2025-04-25 01:38:50 DEBUG] [activity:260]   => succeeded with '{'status': 200, 'headers': {'X-Powered-By': 'Express', 'Content-Type': 'application/json; charset=utf-8', 'Content-Length': '30', 'ETag': 'W/"1e-UF0jTsFD9vB+n1yXcauIzFvQUGs"', 'Date': 'Fri, 25 Apr 2025 01:38:50 GMT', 'Connection': 'keep-alive', 'Keep-Alive': 'timeout=5'}, 'body': '{"status":"ok","redis":"pong"}'}'
[36m[2025-04-25 01:38:50 DEBUG] [__init__:472] No controls to apply on 'activity'
[36m[2025-04-25 01:38:50 DEBUG] [hypothesis:247] allowed tolerance is 200
[32m[2025-04-25 01:38:50 INFO] [hypothesis:260] Steady state hypothesis is met!
[36m[2025-04-25 01:38:50 DEBUG] [__init__:472] No controls to apply on 'hypothesis'
[32m[2025-04-25 01:38:50 INFO] [run:778] Playing your experiment's method now...
[36m[2025-04-25 01:38:50 DEBUG] [__init__:472] No controls to apply on 'method'
[36m[2025-04-25 01:38:50 DEBUG] [__init__:472] No controls to apply on 'activity'
[32m[2025-04-25 01:38:50 INFO] [activity:232] Action: parar_container_redis
[36m[2025-04-25 01:38:50 DEBUG] [process:52] Running: /usr/bin/docker stop redis
[36m[2025-04-25 01:38:50 DEBUG] [activity:260]   => succeeded with '{'status': 0, 'stdout': 'redis\n', 'stderr': ''}'
[36m[2025-04-25 01:38:50 DEBUG] [__init__:472] No controls to apply on 'activity'
[36m[2025-04-25 01:38:50 DEBUG] [__init__:472] No controls to apply on 'activity'
[32m[2025-04-25 01:38:50 INFO] [activity:232] Probe: verifica_servico_aplicacao_apos_falha
[36m[2025-04-25 01:38:53 DEBUG] [activity:317] Activity failed
    Traceback (most recent call last):
      File "/usr/local/lib/python3.11/site-packages/urllib3/connectionpool.py", line 534, in _make_request
        response = conn.getresponse()
                   ^^^^^^^^^^^^^^^^^^
      File "/usr/local/lib/python3.11/site-packages/urllib3/connection.py", line 516, in getresponse
        httplib_response = super().getresponse()
                           ^^^^^^^^^^^^^^^^^^^^^
      File "/usr/local/lib/python3.11/http/client.py", line 1395, in getresponse
        response.begin()
      File "/usr/local/lib/python3.11/http/client.py", line 325, in begin
        version, status, reason = self._read_status()
                                  ^^^^^^^^^^^^^^^^^^^
      File "/usr/local/lib/python3.11/http/client.py", line 286, in _read_status
        line = str(self.fp.readline(_MAXLINE + 1), "iso-8859-1")
                   ^^^^^^^^^^^^^^^^^^^^^^^^^^^^^^
      File "/usr/local/lib/python3.11/socket.py", line 718, in readinto
        return self._sock.recv_into(b)
               ^^^^^^^^^^^^^^^^^^^^^^^
    TimeoutError: timed out
    
    The above exception was the direct cause of the following exception:
    
    Traceback (most recent call last):
      File "/usr/local/lib/python3.11/site-packages/requests/adapters.py", line 667, in send
        resp = conn.urlopen(
               ^^^^^^^^^^^^^
      File "/usr/local/lib/python3.11/site-packages/urllib3/connectionpool.py", line 841, in urlopen
        retries = retries.increment(
                  ^^^^^^^^^^^^^^^^^^
      File "/usr/local/lib/python3.11/site-packages/urllib3/util/retry.py", line 474, in increment
        raise reraise(type(error), error, _stacktrace)
              ^^^^^^^^^^^^^^^^^^^^^^^^^^^^^^^^^^^^^^^^
      File "/usr/local/lib/python3.11/site-packages/urllib3/util/util.py", line 39, in reraise
        raise value
      File "/usr/local/lib/python3.11/site-packages/urllib3/connectionpool.py", line 787, in urlopen
        response = self._make_request(
                   ^^^^^^^^^^^^^^^^^^^
      File "/usr/local/lib/python3.11/site-packages/urllib3/connectionpool.py", line 536, in _make_request
        self._raise_timeout(err=e, url=url, timeout_value=read_timeout)
      File "/usr/local/lib/python3.11/site-packages/urllib3/connectionpool.py", line 367, in _raise_timeout
        raise ReadTimeoutError(
    urllib3.exceptions.ReadTimeoutError: HTTPConnectionPool(host='node-redis-app', port=3000): Read timed out. (read timeout=3)
    
    During handling of the above exception, another exception occurred:
    
    Traceback (most recent call last):
      File "/usr/local/lib/python3.11/site-packages/chaoslib/provider/http.py", line 51, in run_http_activity
        r = s.get(
            ^^^^^^
      File "/usr/local/lib/python3.11/site-packages/requests/sessions.py", line 602, in get
        return self.request("GET", url, **kwargs)
               ^^^^^^^^^^^^^^^^^^^^^^^^^^^^^^^^^^
      File "/usr/local/lib/python3.11/site-packages/requests/sessions.py", line 589, in request
        resp = self.send(prep, **send_kwargs)
               ^^^^^^^^^^^^^^^^^^^^^^^^^^^^^^
      File "/usr/local/lib/python3.11/site-packages/requests/sessions.py", line 703, in send
        r = adapter.send(request, **kwargs)
            ^^^^^^^^^^^^^^^^^^^^^^^^^^^^^^^
      File "/usr/local/lib/python3.11/site-packages/requests/adapters.py", line 713, in send
        raise ReadTimeout(e, request=request)
    requests.exceptions.ReadTimeout: HTTPConnectionPool(host='node-redis-app', port=3000): Read timed out. (read timeout=3)
    
    During handling of the above exception, another exception occurred:
    
    Traceback (most recent call last):
      File "/usr/local/lib/python3.11/site-packages/chaoslib/activity.py", line 314, in run_activity
        result = run_http_activity(activity, configuration, secrets)
                 ^^^^^^^^^^^^^^^^^^^^^^^^^^^^^^^^^^^^^^^^^^^^^^^^^^^
      File "/usr/local/lib/python3.11/site-packages/chaoslib/provider/http.py", line 103, in run_http_activity
        raise ActivityFailed("activity took too long to complete")
    chaoslib.exceptions.ActivityFailed: activity took too long to complete
[31m[2025-04-25 01:38:53 ERROR] [activity:268]   => failed: activity took too long to complete
[36m[2025-04-25 01:38:53 DEBUG] [__init__:472] No controls to apply on 'activity'
[36m[2025-04-25 01:38:53 DEBUG] [__init__:472] No controls to apply on 'activity'
[32m[2025-04-25 01:38:53 INFO] [activity:232] Action: iniciar_container_redis
[36m[2025-04-25 01:38:53 DEBUG] [process:52] Running: /usr/bin/docker start redis
[36m[2025-04-25 01:38:54 DEBUG] [activity:260]   => succeeded with '{'status': 0, 'stdout': 'redis\n', 'stderr': ''}'
[36m[2025-04-25 01:38:54 DEBUG] [__init__:472] No controls to apply on 'activity'
[36m[2025-04-25 01:38:54 DEBUG] [__init__:472] No controls to apply on 'method'
[36m[2025-04-25 01:38:54 DEBUG] [run:696] Running steady-state hypothesis after the method
[32m[2025-04-25 01:38:54 INFO] [hypothesis:205] Steady state hypothesis: AplicaÃ§Ã£o estÃ¡ saudÃ¡vel
[36m[2025-04-25 01:38:54 DEBUG] [__init__:472] No controls to apply on 'hypothesis'
[36m[2025-04-25 01:38:54 DEBUG] [__init__:472] No controls to apply on 'activity'
[32m[2025-04-25 01:38:54 INFO] [activity:232] Probe: verifica_servico_aplicacao
[36m[2025-04-25 01:38:55 DEBUG] [activity:260]   => succeeded with '{'status': 200, 'headers': {'X-Powered-By': 'Express', 'Content-Type': 'application/json; charset=utf-8', 'Content-Length': '30', 'ETag': 'W/"1e-UF0jTsFD9vB+n1yXcauIzFvQUGs"', 'Date': 'Fri, 25 Apr 2025 01:38:55 GMT', 'Connection': 'keep-alive', 'Keep-Alive': 'timeout=5'}, 'body': '{"status":"ok","redis":"pong"}'}'
[36m[2025-04-25 01:38:55 DEBUG] [__init__:472] No controls to apply on 'activity'
[36m[2025-04-25 01:38:55 DEBUG] [hypothesis:247] allowed tolerance is 200
[32m[2025-04-25 01:38:55 INFO] [hypothesis:260] Steady state hypothesis is met!
[36m[2025-04-25 01:38:55 DEBUG] [__init__:472] No controls to apply on 'hypothesis'
[32m[2025-04-25 01:38:55 INFO] [run:1072] Let's rollback...
[36m[2025-04-25 01:38:55 DEBUG] [__init__:472] No controls to apply on 'rollback'
[32m[2025-04-25 01:38:55 INFO] [rollback:33] No declared rollbacks, let's move on.
[36m[2025-04-25 01:38:55 DEBUG] [__init__:472] No controls to apply on 'rollback'
[32m[2025-04-25 01:38:55 INFO] [run:598] Experiment ended with status: completed
[36m[2025-04-25 01:38:55 DEBUG] [__init__:472] No controls to apply on 'experiment'
[36m[2025-04-25 01:38:55 DEBUG] [__init__:106] Cleaning up controls
[36m[2025-04-25 01:38:55 DEBUG] [caching:42] Clearing activities cache
